<?xml version="1.0" ?>
<!-- =================================================================================== -->
<!-- |    This document was autogenerated by xacro from iiwa_striker.urdf.xacro        | -->
<!-- |    EDITING THIS FILE BY HAND IS NOT RECOMMENDED                                 | -->
<!-- =================================================================================== -->
<robot name="iiwa_striker">
  <material name="Black">
    <color rgba="0.0 0.0 0.0 1.0"/>
  </material>
  <material name="Blue">
    <color rgba="0.0 0.0 0.8 1.0"/>
  </material>
  <material name="Green">
    <color rgba="0.0 0.8 0.0 1.0"/>
  </material>
  <material name="Grey">
    <color rgba="0.4 0.4 0.4 1.0"/>
  </material>
  <material name="Orange">
    <color rgba="1.0 0.4235294117647059 0.0392156862745098 1.0"/>
  </material>
  <material name="Brown">
    <color rgba="0.8705882352941177 0.8117647058823529 0.7647058823529411 1.0"/>
  </material>
  <material name="Red">
    <color rgba="0.8 0.0 0.0 1.0"/>
  </material>
  <material name="White">
    <color rgba="1.0 1.0 1.0 1.0"/>
  </material>
  <material name="LightGrey">
    <color rgba="0.3 0.3 0.3 1.0"/>
  </material>
  <link name="world"/>
  <!--joint between {parent} and link_0-->
  <joint name="world_F_base_joint" type="fixed">
    <origin rpy="0 0 0" xyz="0 0 0"/>
    <parent link="world"/>
    <child link="F_link_0"/>
  </joint>
  <link name="F_link_0">
    <inertial>
      <!--  Fixed
        <origin xyz="-0.1 0 0.07" rpy="0 0 0"/>
        <mass value="5"/>
        <inertia ixx="0.05"  ixy="0"  ixz="0" iyy="0.06" iyz="0" izz="0.03" />
        -->
      <!-- CAD -->
      <mass value="5.476713"/>
      <origin rpy="0 0 0" xyz="-0.012882 -0.000000 0.071517"/>
      <inertia ixx="2.4243e-02" ixy="2.0000e-08" ixz="6.7180e-04" iyy="3.0840e-02" iyz="-1.9000e-07" izz="3.3475e-02"/>
    </inertial>
    <visual>
      <origin rpy="0 0 0" xyz="0 0 0"/>
      <geometry>
        <mesh filename="./meshes_new/iiwa/visual/link_0.stl"/>
      </geometry>
      <material name="Grey"/>
    </visual>
    <collision>
      <origin rpy="0 0 0" xyz="0 0 0"/>
      <geometry>
        <mesh filename="./meshes_new/iiwa/collision/link_0.stl"/>
      </geometry>
      <material name="Grey"/>
    </collision>
    <self_collision_checking>
      <origin rpy="0 0 0" xyz="0 0 0"/>
      <geometry>
        <capsule length="0.25" radius="0.15"/>
      </geometry>
    </self_collision_checking>
  </link>
  <!-- joint between link_0 and link_1 -->
  <joint name="F_joint_1" type="revolute">
    <parent link="F_link_0"/>
    <child link="F_link_1"/>
    <origin rpy="0 0 0" xyz="0 0 0.1575"/>
    <axis xyz="0 0 1"/>
    <limit effort="320" lower="-2.9670597283903604" upper="2.9670597283903604" velocity="1.4835298641951802"/>
    <safety_controller k_position="100" k_velocity="10" soft_lower_limit="-2.9321531433504737" soft_upper_limit="2.9321531433504737"/>
    <dynamics damping="0.24150" friction="0.31909"/>
    <!-- ETH -->
    <!--      <dynamics damping="0.330320"  friction="0.384477"/>-->
  </joint>
  <link name="F_link_1">
    <inertial>
      <!-- ETH
        <origin xyz="-0.003508 0.001602 -0.03139" rpy="0 0 0"/>
        <mass value="3.947808"/>
        <inertia ixx="0.004554"  ixy="0.00000"  ixz="-0.00000" iyy="0.00454" iyz="0.00001" izz="0.00029" />
        -->
      <!-- SysId
          <mass value="2.356723"/>
          <origin xyz="0.000000 0.000000 -0.249990" rpy="0 0 0"/>
          <inertia ixx="0.099939"  ixy="-0.000029"  iyy="0.099716" ixz="-0.000026" iyz="0.000099" izz="0.001000" />
        -->
      <!-- CAD -->
      <mass value="4.100238"/>
      <origin rpy="0 0 0" xyz="0.000004 -0.033790 0.122349"/>
      <inertia ixx="3.2869e-02" ixy="-4.3000e-07" ixz="9.4000e-07" iyy="3.3168e-02" iyz="4.8970e-03" izz="1.2274e-02"/>
    </inertial>
    <visual>
      <origin rpy="0 0 0" xyz="0 0 0"/>
      <geometry>
        <mesh filename="./meshes_new/iiwa/visual/link_1.stl"/>
      </geometry>
      <material name="Orange"/>
    </visual>
    <collision>
      <origin rpy="0 0 0" xyz="0 0 0"/>
      <geometry>
        <mesh filename="./meshes_new/iiwa/collision/link_1.stl"/>
      </geometry>
      <material name="Orange"/>
    </collision>
  </link>
  <!-- joint between link_1 and link_2 -->
  <joint name="F_joint_2" type="revolute">
    <parent link="F_link_1"/>
    <child link="F_link_2"/>
    <origin rpy="1.5707963267948966   0 3.141592653589793" xyz="0 0 0.2025"/>
    <axis xyz="0 0 1"/>
    <limit effort="320" lower="-2.0943951023931953" upper="2.0943951023931953" velocity="1.4835298641951802"/>
    <safety_controller k_position="100" k_velocity="10" soft_lower_limit="-2.0594885173533086" soft_upper_limit="2.0594885173533086"/>
    <dynamics damping="0.37328" friction="0.18130"/>
    <!-- ETH -->
    <!--        <dynamics damping="0.212160"  friction="0.496333"/>-->
  </joint>
  <link name="F_link_2">
    <inertial>
      <!-- ETH
          <mass value="4.502752"/>
          <origin xyz="-0.007671 0.166693  -0.003551" rpy="0 0 0"/>
          <inertia ixx="0.00032"  ixy="0.00000"  ixz="0.000007" iyy="0.000100" iyz="-0.000003" izz="0.000419" />
        -->
      <!-- SysID
          <mass value="6.000000"/>
          <origin xyz="-0.004595 0.150863 0.028496" rpy="0 0 0"/>
          <inertia ixx="0.030001"  ixy="-0.000999"  iyy="0.010000" ixz="0.000999" iyz="-0.000999" izz="0.030001" />
        -->
      <!-- CAD -->
      <mass value="3.943457"/>
      <origin rpy="0 0 0" xyz="0.000285 0.058872 0.041961"/>
      <inertia ixx="3.0495e-02" ixy="-3.2800e-05" ixz="2.2370e-05" iyy="1.0969e-02" iyz="4.8615e-03" izz="3.0330e-02"/>
    </inertial>
    <visual>
      <origin rpy="0 0 0" xyz="0 0 0"/>
      <geometry>
        <mesh filename="./meshes_new/iiwa/visual/link_2.stl"/>
      </geometry>
      <material name="Orange"/>
    </visual>
    <collision>
      <origin rpy="0 0 0" xyz="0 0 0"/>
      <geometry>
        <mesh filename="./meshes_new/iiwa/collision/link_2.stl"/>
      </geometry>
      <material name="Orange"/>
    </collision>
  </link>
  <!-- joint between link_2 and link_3 -->
  <joint name="F_joint_3" type="revolute">
    <parent link="F_link_2"/>
    <child link="F_link_3"/>
    <origin rpy="1.5707963267948966 0 3.141592653589793" xyz="0 0.2045 0"/>
    <axis xyz="0 0 1"/>
    <limit effort="176" lower="-2.9670597283903604" upper="2.9670597283903604" velocity="1.7453292519943295"/>
    <safety_controller k_position="100" k_velocity="10" soft_lower_limit="-2.9321531433504737" soft_upper_limit="2.9321531433504737"/>
    <dynamics damping="0.11025" friction="0.07302"/>
    <!-- ETH -->
    <!--        <dynamics damping="0.100000"  friction="0.173951"/>-->
  </joint>
  <link name="F_link_3">
    <inertial>
      <!-- ETH
        <mass value="2.455197"/>
        <origin xyz="-0.002246 -0.034918 -0.02652" rpy="0 0 0"/>
        <inertia ixx="0.002233"  ixy="-0.000046"  ixz="0.000068" iyy="0.002191" iyz="0.000072" izz="0.000725" />
        -->
      <!-- SysId
        <mass value="6.00000"/>
        <origin xyz="-0.006630 -0.001947 -0.057071" rpy="0 0 0"/>
        <inertia ixx="0.003001"  ixy="-0.000999"  iyy="0.030001" ixz="0.000999" iyz="-0.000999" izz="0.010000" />
        -->
      <!-- CAD -->
      <mass value="4"/>
      <origin rpy="0 0 0" xyz="0.000002 0.029546 0.126448"/>
      <inertia ixx="3.1546e-02" ixy="-3.6628e-07" ixz="-3.9154e-07" iyy="2.9954e-02" iyz="-6.1227e-03" izz="9.5594e-03"/>
    </inertial>
    <visual>
      <origin rpy="0 0 0" xyz="0 0 0"/>
      <geometry>
        <mesh filename="./meshes_new/iiwa/visual/link_3.stl"/>
      </geometry>
      <material name="Orange"/>
    </visual>
    <collision>
      <origin rpy="0 0 0" xyz="0 0 0"/>
      <geometry>
        <mesh filename="./meshes_new/iiwa/collision/link_3.stl"/>
      </geometry>
      <material name="Orange"/>
    </collision>
  </link>
  <!-- joint between link_3 and link_4 -->
  <joint name="F_joint_4" type="revolute">
    <parent link="F_link_3"/>
    <child link="F_link_4"/>
    <origin rpy="1.5707963267948966 0 0" xyz="0 0 0.2155"/>
    <axis xyz="0 0 1"/>
    <limit effort="176" lower="-2.0943951023931953" upper="2.0943951023931953" velocity="1.3089969389957472"/>
    <safety_controller k_position="100" k_velocity="10" soft_lower_limit="-2.0594885173533086" soft_upper_limit="2.0594885173533086"/>
    <dynamics damping="0.10000" friction="0.17671"/>
    <!-- ETH -->
    <!--        <dynamics damping="0.219041"  friction="0.375100"/>-->
  </joint>
  <link name="F_link_4">
    <inertial>
      <!-- ETH
          <mass value="2.611550"/>
          <origin xyz="0.000196 -0.052679 0.038182" rpy="0 0 0"/>
          <inertia ixx="0.038444"  ixy="0.000880"  ixz="-0.001120" iyy="0.011437" iyz="-0.001113" izz=" 0.049880" />
          -->
      <!-- SysId
          <mass value="1.224529"/>
          <origin xyz="0.044234 0.050000 0.006944" rpy="0 0 0"/>
          <inertia ixx="0.003001"  ixy="0.000099"  iyy="0.001000" ixz="-0.000099" iyz="0.000099" izz="0.003001" />
          -->
      <mass value="4"/>
      <origin rpy="0 0 0" xyz="-0.000000 0.067480 0.034254"/>
      <inertia ixx="2.5087e-02" ixy="-4.3896e-08" ixz="-1.3169e-07" iyy="8.9416e-03" iyz="4.1448e-03" izz="2.3916e-02"/>
    </inertial>
    <visual>
      <origin rpy="0 0 0" xyz="0 0 0"/>
      <geometry>
        <mesh filename="./meshes_new/iiwa/visual/link_4.stl"/>
      </geometry>
      <material name="Orange"/>
    </visual>
    <collision>
      <origin rpy="0 0 0" xyz="0 0 0"/>
      <geometry>
        <mesh filename="./meshes_new/iiwa/collision/link_4.stl"/>
      </geometry>
      <material name="Orange"/>
    </collision>
  </link>
  <!-- joint between link_4 and link_5 -->
  <joint name="F_joint_5" type="revolute">
    <parent link="F_link_4"/>
    <child link="F_link_5"/>
    <origin rpy="-1.5707963267948966 3.141592653589793 0" xyz="0 0.1845 0"/>
    <axis xyz="0 0 1"/>
    <limit effort="110" lower="-2.9670597283903604" upper="2.9670597283903604" velocity="2.2689280275926285"/>
    <safety_controller k_position="100" k_velocity="10" soft_lower_limit="-2.9321531433504737" soft_upper_limit="2.9321531433504737"/>
    <dynamics damping="0.10000" friction="0.03463"/>
    <!-- ETH -->
    <!--        <dynamics damping="0.185923"  friction="0.481099"/>-->
  </joint>
  <link name="F_link_5">
    <inertial>
      <!-- ETH
        <mass value="3.410009"/>
        <origin xyz="0.000054  -0.002367 -0.21134" rpy="0 0 0"/>
        <inertia ixx="0.002769"  ixy="-0.000008"  ixz="0.000006" iyy="0.002842" iyz="-0.000001" izz="0.000117" />
        -->
      <!-- SysId
        <mass value="6.00000"/>
        <origin xyz="-0.002930 0.015256 0.035846" rpy="0 0 0"/>
        <inertia ixx="0.003001"  ixy="-0.000099"  iyy="0.003001" ixz="-0.000099" iyz="0.000099" izz="0.001000" />
        -->
      <mass value="3.2"/>
      <origin rpy="0 0 0" xyz="0.000125 0.021388 0.075417"/>
      <inertia ixx="1.9009e-02" ixy="3.3348e-06" ixz="2.9559e-06" iyy="1.6414e-02" iyz="-5.8267e-03" izz="8.4231e-03"/>
    </inertial>
    <visual>
      <origin rpy="0 0 0" xyz="0 0 0"/>
      <geometry>
        <mesh filename="./meshes_new/iiwa/visual/link_5.stl"/>
      </geometry>
      <material name="Orange"/>
    </visual>
    <collision>
      <origin rpy="0 0 0" xyz="0 0 0"/>
      <geometry>
        <mesh filename="./meshes_new/iiwa/collision/link_5.stl"/>
      </geometry>
      <material name="Orange"/>
    </collision>
  </link>
  <!-- joint between link_5 and link_6 -->
  <joint name="F_joint_6" type="revolute">
    <parent link="F_link_5"/>
    <child link="F_link_6"/>
    <origin rpy="1.5707963267948966 0 0" xyz="0 0 0.2155"/>
    <axis xyz="0 0 1"/>
    <limit effort="40" lower="-2.0943951023931953" upper="2.0943951023931953" velocity="2.356194490192345"/>
    <safety_controller k_position="100" k_velocity="10" soft_lower_limit="-2.0594885173533086" soft_upper_limit="2.0594885173533086"/>
    <dynamics damping="0.12484" friction="0.13391"/>
    <!-- ETH -->
    <!--        <dynamics damping="0.100000"  friction="0.196149"/>-->
  </joint>
  <link name="F_link_6">
    <inertial>
      <!-- ETH
        <mass value="3.387949"/>
        <origin xyz="0.000492  0.020190  -0.027496" rpy="0 0 0"/>
        <inertia ixx="0.000500"  ixy="-0.000050"  ixz="-0.000024" iyy="0.002809" iyz="-0.000041" izz="0.002315" />
        -->
      <!-- SysId
        <mass value="1.410742"/>
        <origin xyz="0.015383 -0.046263 0.011131" rpy="0 0 0"/>
        <inertia ixx="0.001000"  ixy="0.000099"  iyy="0.001000" ixz="0.000099" iyz="0.000099" izz="0.001000" />
        -->
      <!-- CAD -->
      <mass value="2.2"/>
      <origin rpy="0 0 0" xyz="-0.000000 0.002431 -0.001270"/>
      <inertia ixx="6.1583e-03" ixy="3.4928e-08" ixz="-1.9792e-07" iyy="4.4451e-03" iyz="3.2555e-04" izz="5.7995e-03"/>
    </inertial>
    <visual>
      <origin rpy="0 0 0" xyz="0 0 0"/>
      <geometry>
        <mesh filename="./meshes_new/iiwa/visual/link_6.stl"/>
      </geometry>
      <material name="Orange"/>
    </visual>
    <collision>
      <origin rpy="0 0 0" xyz="0 0 0"/>
      <geometry>
        <mesh filename="./meshes_new/iiwa/collision/link_6.stl"/>
      </geometry>
      <material name="Orange"/>
    </collision>
  </link>
  <!-- joint between link_6 and link_7 -->
  <joint name="F_joint_7" type="revolute">
    <parent link="F_link_6"/>
    <child link="F_link_7"/>
    <origin rpy="-1.5707963267948966 3.141592653589793 0" xyz="0 0.081 0"/>
    <axis xyz="0 0 1"/>
    <limit effort="40" lower="-3.0543261909900763" upper="3.0543261909900763" velocity="2.356194490192345"/>
    <safety_controller k_position="100" k_velocity="10" soft_lower_limit="-3.01941960595019" soft_upper_limit="3.01941960595019"/>
    <dynamics damping="0.10000" friction="0.08710"/>
    <!-- ETH -->
    <!--        <dynamics damping="0.100000"  friction="0.05"/>-->
  </joint>
  <link name="F_link_7">
    <inertial>
      <!-- ETH
        <mass value="0.354321"/>
        <origin xyz="-0.034656 -0.023242 0.07138" rpy="0 0 0"/>
        <inertia ixx="0.007946"  ixy="0.000221"  ixz="-0.000294" iyy=" 0.010889" iyz="-0.000294" izz="0.002944" />
        -->
      <!-- SysId
        <mass value="1.00000"/>
        <origin xyz="0.001241 0.004168 0.100000" rpy="0 0 0"/>
        <inertia ixx="0.001000"  ixy="-0.000099"  iyy="0.001000" ixz="-0.000099" iyz="0.000099" izz="0.001000" />
        -->
      <!-- CAD -->
      <mass value="0.4"/>
      <origin rpy="0 0 0" xyz="0.000540 0.000569 0.026582"/>
      <inertia ixx="3.5211e-04" ixy="-1.4790e-07" ixz="4.7514e-06" iyy="3.5066e-04" iyz="-7.8574e-07" izz="4.3803e-04"/>
    </inertial>
    <visual>
      <origin rpy="0 0 0" xyz="0 0 0"/>
      <geometry>
        <mesh filename="./meshes_new/iiwa/visual/link_7.stl"/>
      </geometry>
      <material name="Grey"/>
    </visual>
    <collision>
      <origin rpy="0 0 0" xyz="0 0 0"/>
      <geometry>
        <mesh filename="./meshes_new/iiwa/collision/link_7.stl"/>
      </geometry>
      <material name="Grey"/>
    </collision>
  </link>
  <joint name="F_joint_ee" type="fixed">
    <parent link="F_link_7"/>
    <child link="F_link_ee"/>
    <origin rpy="0 0 0" xyz="0 0 0.07"/>
  </joint>
  <link name="F_link_ee">
    <inertial>
      <origin rpy="0 0 0" xyz="0 0 0.0"/>
      <mass value="0.0"/>
      <inertia ixx="0.0" ixy="0.0" ixz="0.0" iyy="0.0" iyz="0.0" izz="0.0"/>
    </inertial>
  </link>
  <!-- Link0 -->
  <gazebo reference="F_link_0">
    <material>Gazebo/Grey</material>
    <mu1>0.2</mu1>
    <mu2>0.2</mu2>
    <selfCollide>0</selfCollide>
  </gazebo>
  <!-- Link1 -->
  <gazebo reference="F_link_1">
    <material>Gazebo/Orange</material>
    <mu1>0.2</mu1>
    <mu2>0.2</mu2>
    <selfCollide>0</selfCollide>
  </gazebo>
  <!-- Link2 -->
  <gazebo reference="F_link_2">
    <material>Gazebo/Orange</material>
    <mu1>0.2</mu1>
    <mu2>0.2</mu2>
    <selfCollide>0</selfCollide>
  </gazebo>
  <!-- Link3 -->
  <gazebo reference="F_link_3">
    <material>Gazebo/Orange</material>
    <mu1>0.2</mu1>
    <mu2>0.2</mu2>
    <selfCollide>0</selfCollide>
  </gazebo>
  <!-- Link4 -->
  <gazebo reference="F_link_4">
    <material>Gazebo/Orange</material>
    <mu1>0.2</mu1>
    <mu2>0.2</mu2>
    <selfCollide>0</selfCollide>
  </gazebo>
  <!-- Link5 -->
  <gazebo reference="F_link_5">
    <material>Gazebo/Orange</material>
    <mu1>0.2</mu1>
    <mu2>0.2</mu2>
    <selfCollide>0</selfCollide>
  </gazebo>
  <!-- Link6 -->
  <gazebo reference="F_link_6">
    <material>Gazebo/Orange</material>
    <mu1>0.2</mu1>
    <mu2>0.2</mu2>
    <selfCollide>0</selfCollide>
  </gazebo>
  <!-- Link7 -->
  <gazebo reference="F_link_7">
    <material>Gazebo/Grey</material>
    <mu1>0.2</mu1>
    <mu2>0.2</mu2>
    <selfCollide>0</selfCollide>
  </gazebo>
  <!-- Link7 -->
  <gazebo reference="F_joint_ee">
    <preserveFixedJoint>1</preserveFixedJoint>
  </gazebo>
  <transmission name="F_tran_1">
    <robotNamespace>/F</robotNamespace>
    <type>transmission_interface/SimpleTransmission</type>
    <joint name="F_joint_1">
      <hardwareInterface>hardware_interface/PositionJointInterface</hardwareInterface>
    </joint>
    <actuator name="F_motor_1">
      <hardwareInterface>hardware_interface/PositionJointInterface</hardwareInterface>
      <mechanicalReduction>1</mechanicalReduction>
    </actuator>
  </transmission>
  <transmission name="F_tran_2">
    <robotNamespace>/F</robotNamespace>
    <type>transmission_interface/SimpleTransmission</type>
    <joint name="F_joint_2">
      <hardwareInterface>hardware_interface/PositionJointInterface</hardwareInterface>
    </joint>
    <actuator name="F_motor_2">
      <hardwareInterface>hardware_interface/PositionJointInterface</hardwareInterface>
      <mechanicalReduction>1</mechanicalReduction>
    </actuator>
  </transmission>
  <transmission name="F_tran_3">
    <robotNamespace>/F</robotNamespace>
    <type>transmission_interface/SimpleTransmission</type>
    <joint name="F_joint_3">
      <hardwareInterface>hardware_interface/PositionJointInterface</hardwareInterface>
    </joint>
    <actuator name="F_motor_3">
      <hardwareInterface>hardware_interface/PositionJointInterface</hardwareInterface>
      <mechanicalReduction>1</mechanicalReduction>
    </actuator>
  </transmission>
  <transmission name="F_tran_4">
    <robotNamespace>/F</robotNamespace>
    <type>transmission_interface/SimpleTransmission</type>
    <joint name="F_joint_4">
      <hardwareInterface>hardware_interface/PositionJointInterface</hardwareInterface>
    </joint>
    <actuator name="F_motor_4">
      <hardwareInterface>hardware_interface/PositionJointInterface</hardwareInterface>
      <mechanicalReduction>1</mechanicalReduction>
    </actuator>
  </transmission>
  <transmission name="F_tran_5">
    <robotNamespace>/F</robotNamespace>
    <type>transmission_interface/SimpleTransmission</type>
    <joint name="F_joint_5">
      <hardwareInterface>hardware_interface/PositionJointInterface</hardwareInterface>
    </joint>
    <actuator name="F_motor_5">
      <hardwareInterface>hardware_interface/PositionJointInterface</hardwareInterface>
      <mechanicalReduction>1</mechanicalReduction>
    </actuator>
  </transmission>
  <transmission name="F_tran_6">
    <robotNamespace>/F</robotNamespace>
    <type>transmission_interface/SimpleTransmission</type>
    <joint name="F_joint_6">
      <hardwareInterface>hardware_interface/PositionJointInterface</hardwareInterface>
    </joint>
    <actuator name="F_motor_6">
      <hardwareInterface>hardware_interface/PositionJointInterface</hardwareInterface>
      <mechanicalReduction>1</mechanicalReduction>
    </actuator>
  </transmission>
  <transmission name="F_tran_7">
    <robotNamespace>/F</robotNamespace>
    <type>transmission_interface/SimpleTransmission</type>
    <joint name="F_joint_7">
      <hardwareInterface>hardware_interface/PositionJointInterface</hardwareInterface>
    </joint>
    <actuator name="F_motor_7">
      <hardwareInterface>hardware_interface/PositionJointInterface</hardwareInterface>
      <mechanicalReduction>1</mechanicalReduction>
    </actuator>
  </transmission>
  <joint name="F_striker" type="fixed">
    <parent link="F_link_ee"/>
    <child link="F_striker_tip"/>
    <origin rpy="0 0 0" xyz="0.0 0.0 0.515"/>
  </joint>
  <link name="F_striker_tip">
    <inertial>
      <origin rpy="0 0 0" xyz="0 0 -0.359"/>
      <mass value="0.350"/>
      <inertia ixx="0.001" ixy="0.0" ixz="0.0" iyy="0.001" iyz="0.0" izz="0.001"/>
    </inertial>
    <visual>
      <origin rpy="0 0.0 0" xyz="0 0 -0.515"/>
      <geometry>
        <mesh filename="./meshes_new/striker/visual/EE_arm.stl"/>
      </geometry>
      <material name="LightGrey"/>
    </visual>
    <collision>
      <origin rpy="0 0 0" xyz="0 0 -0.515"/>
      <geometry>
        <mesh filename="./meshes_new/striker/collision/EE_arm_collision.stl"/>
      </geometry>
    </collision>
  </link>
  <joint name="F_striker_joint_1" type="revolute">
    <parent link="F_striker_tip"/>
    <child link="F_striker_joint_link"/>
    <origin rpy="0 0 0" xyz="0.0 0.0 0.0"/>
    <axis xyz="0 1 0"/>
    <limit effort="1" lower="-1.5707963267948966" upper="1.5707963267948966" velocity="3.1415926"/>
    <safety_controller k_position="100" k_velocity="10" soft_lower_limit="-2.094395102" soft_upper_limit="2.094395102"/>
    <dynamics damping="0.05"/>
  </joint>
  <link name="F_striker_joint_link">
    <inertial>
      <origin rpy="0 0 0" xyz="0 0.0 0"/>
      <mass value="0.05"/>
      <inertia ixx="0.001" ixy="0.0" ixz="0.0" iyy="0.001" iyz="0.0" izz="0.001"/>
    </inertial>
  </link>
  <joint name="F_striker_joint_2" type="revolute">
    <parent link="F_striker_joint_link"/>
    <child link="F_striker_mallet"/>
    <origin rpy="0 0 0" xyz="0.0 0.0 0.0"/>
    <axis xyz="1 0 0"/>
    <limit effort="1" lower="-1.5707963267948966" upper="1.5707963267948966" velocity="3.1415926"/>
    <safety_controller k_position="100" k_velocity="10" soft_lower_limit="-2.094395102" soft_upper_limit="2.094395102"/>
    <dynamics damping="0.05"/>
  </joint>
  <link name="F_striker_mallet">
    <inertial>
      <origin rpy="0 0 0" xyz="0 0.0 0.0645"/>
      <mass value="0.183"/>
      <inertia ixx="0.01" ixy="0.0" ixz="0.0" iyy="0.01" iyz="0.0" izz="0.01"/>
    </inertial>
    <visual>
      <origin rpy="0.0 0.0 0" xyz="0 0.0 0.0"/>
      <geometry>
        <mesh filename="./meshes_new/striker/visual/EE_mallet_foam.stl"/>
      </geometry>
      <material name="LightGrey"/>
    </visual>
    <collision>
      <origin rpy="0.0 0.0 0" xyz="0 0.0 0.0455"/>
      <geometry>
        <cylinder length="0.04" radius="0.04815"/>
      </geometry>
    </collision>
  </link>
  <joint name="F_striker_mallet_fix" type="fixed">
    <parent link="F_striker_mallet"/>
    <child link="F_striker_mallet_tip"/>
    <origin rpy="0 0 0" xyz="0.0 0.0 0.0645"/>
    <axis xyz="1 0 0"/>
  </joint>
  <!--  The striker frame is here defined -->
  <link name="F_striker_mallet_tip">
    <inertial>
      <origin rpy="0 0 0" xyz="0 0 0.0"/>
      <mass value="0.05"/>
      <inertia ixx="0.001" ixy="0.0" ixz="0.0" iyy="0.001" iyz="0.0" izz="0.001"/>
    </inertial>
  </link>
  <gazebo reference="F_striker_tip">
    <collision>
      <surface>
        <bounce>
          <restitution_coefficient>1.0</restitution_coefficient>
          <threshold>0.0</threshold>
        </bounce>
        <contact>
          <collide_bitmask>0x02</collide_bitmask>
          <ode>
            <kp>1e9</kp>
            <max_vel>10</max_vel>
          </ode>
        </contact>
      </surface>
    </collision>
    <material>Gazebo/Grey</material>
    <mu1>1.0</mu1>
    <mu2>1.0</mu2>
    <selfCollide>0</selfCollide>
  </gazebo>
  <gazebo reference="F_striker_joint_link">
    <collision>
      <surface>
        <bounce>
          <restitution_coefficient>1.0</restitution_coefficient>
          <threshold>0.0</threshold>
        </bounce>
        <contact>
          <collide_bitmask>0x02</collide_bitmask>
          <ode>
            <kp>1e9</kp>
            <max_vel>10</max_vel>
          </ode>
        </contact>
      </surface>
    </collision>
    <material>Gazebo/Grey</material>
    <mu1>1.0</mu1>
    <mu2>1.0</mu2>
    <selfCollide>0</selfCollide>
  </gazebo>
  <gazebo reference="F_striker_mallet">
    <collision>
      <surface>
        <bounce>
          <restitution_coefficient>1.0</restitution_coefficient>
          <threshold>0.0</threshold>
        </bounce>
        <contact>
          <collide_bitmask>0x02</collide_bitmask>
          <ode>
            <kp>1e9</kp>
            <max_vel>10</max_vel>
          </ode>
        </contact>
      </surface>
    </collision>
    <material>Gazebo/Grey</material>
    <mu1>1.0</mu1>
    <mu2>1.0</mu2>
    <selfCollide>0</selfCollide>
  </gazebo>
  <gazebo reference="F_striker_mallet_fix">
    <preserveFixedJoint>1</preserveFixedJoint>
  </gazebo>
  <transmission name="F_striker_tran_1">
    <robotNamespace>/F</robotNamespace>
    <type>transmission_interface/SimpleTransmission</type>
    <joint name="F_striker_joint_1">
      <hardwareInterface>hardware_interface/EffortJointInterface</hardwareInterface>
    </joint>
    <actuator name="F_striker_motor_1">
      <hardwareInterface>hardware_interface/EffortJointInterface</hardwareInterface>
      <mechanicalReduction>1</mechanicalReduction>
    </actuator>
  </transmission>
  <transmission name="F_striker_tran_2">
    <robotNamespace>/F</robotNamespace>
    <type>transmission_interface/SimpleTransmission</type>
    <joint name="F_striker_joint_2">
      <hardwareInterface>hardware_interface/EffortJointInterface</hardwareInterface>
    </joint>
    <actuator name="F_striker_motor_2">
      <hardwareInterface>hardware_interface/EffortJointInterface</hardwareInterface>
      <mechanicalReduction>1</mechanicalReduction>
    </actuator>
  </transmission>
  <gazebo>
    <plugin filename="libuniversal_joint_plugin.so" name="univsersal_joint_plugin">
            </plugin>
  </gazebo>
  <gazebo>
    <plugin filename="libgazebo_ros_control.so" name="gazebo_ros_control">
      <robotSimType>iiwas_gazebo/GravityCompensationHWSim</robotSimType>
    </plugin>
  </gazebo>
</robot>

